2024-03-31 19:30:10,886 - ERROR - Threaded polling exception: A request to the Telegram API was unsuccessful. Error code: 400. Description: Bad Request: file must be non-empty
2024-03-31 19:30:10,887 - ERROR - Exception traceback:
Traceback (most recent call last):
  File "C:\Users\azpp3\PycharmProjects\ryletka23\venv\lib\site-packages\telebot\__init__.py", line 1141, in __threaded_polling
    self.worker_pool.raise_exceptions()
  File "C:\Users\azpp3\PycharmProjects\ryletka23\venv\lib\site-packages\telebot\util.py", line 149, in raise_exceptions
    raise self.exception_info
  File "C:\Users\azpp3\PycharmProjects\ryletka23\venv\lib\site-packages\telebot\util.py", line 92, in run
    task(*args, **kwargs)
  File "C:\Users\azpp3\PycharmProjects\ryletka23\venv\lib\site-packages\telebot\__init__.py", line 7868, in _run_middlewares_and_handler
    result = handler['function'](message)
  File "C:\Users\azpp3\PycharmProjects\ryletka23\bot.py", line 20, in debug
    bot.send_document(message.chat.id, file)
  File "C:\Users\azpp3\PycharmProjects\ryletka23\venv\lib\site-packages\telebot\__init__.py", line 2467, in send_document
    apihelper.send_data(
  File "C:\Users\azpp3\PycharmProjects\ryletka23\venv\lib\site-packages\telebot\apihelper.py", line 923, in send_data
    return _make_request(token, method_url, params=payload, files=files, method='post')
  File "C:\Users\azpp3\PycharmProjects\ryletka23\venv\lib\site-packages\telebot\apihelper.py", line 164, in _make_request
    json_result = _check_result(method_name, result)
  File "C:\Users\azpp3\PycharmProjects\ryletka23\venv\lib\site-packages\telebot\apihelper.py", line 191, in _check_result
    raise ApiTelegramException(method_name, result, result_json)
telebot.apihelper.ApiTelegramException: A request to the Telegram API was unsuccessful. Error code: 400. Description: Bad Request: file must be non-empty

2024-03-31 20:28:31,699 - ERROR - Threaded polling exception: A request to the Telegram API was unsuccessful. Error code: 502. Description: Bad Gateway
2024-03-31 20:28:31,705 - ERROR - Exception traceback:
Traceback (most recent call last):
  File "C:\Users\azpp3\PycharmProjects\ryletka23\venv\lib\site-packages\telebot\__init__.py", line 1140, in __threaded_polling
    polling_thread.raise_exceptions()
  File "C:\Users\azpp3\PycharmProjects\ryletka23\venv\lib\site-packages\telebot\util.py", line 110, in raise_exceptions
    raise self.exception_info
  File "C:\Users\azpp3\PycharmProjects\ryletka23\venv\lib\site-packages\telebot\util.py", line 92, in run
    task(*args, **kwargs)
  File "C:\Users\azpp3\PycharmProjects\ryletka23\venv\lib\site-packages\telebot\__init__.py", line 661, in __retrieve_updates
    updates = self.get_updates(offset=(self.last_update_id + 1),
  File "C:\Users\azpp3\PycharmProjects\ryletka23\venv\lib\site-packages\telebot\__init__.py", line 633, in get_updates
    json_updates = apihelper.get_updates(
  File "C:\Users\azpp3\PycharmProjects\ryletka23\venv\lib\site-packages\telebot\apihelper.py", line 321, in get_updates
    return _make_request(token, method_url, params=payload)
  File "C:\Users\azpp3\PycharmProjects\ryletka23\venv\lib\site-packages\telebot\apihelper.py", line 164, in _make_request
    json_result = _check_result(method_name, result)
  File "C:\Users\azpp3\PycharmProjects\ryletka23\venv\lib\site-packages\telebot\apihelper.py", line 191, in _check_result
    raise ApiTelegramException(method_name, result, result_json)
telebot.apihelper.ApiTelegramException: A request to the Telegram API was unsuccessful. Error code: 502. Description: Bad Gateway

